<mujoco model="hex">
    <compiler angle="radian" meshdir="hex_meshes/"/>
    <size njmax="500" nconmax="100" />

    <default class="main">
        <default class="leg">
            <geom type="mesh" rgba="0.3 0.8 0.9 1" mesh="leg_convex" />
            <joint pos="0 0 0" axis="0 1 0" armature="0.01" damping="0.2" frictionloss="0.00"/>
        </default>

        <default class="leg_actuator">
          <position gear="1.0" kp="15" forcelimited="true" forcerange="-10 10"/>
        </default>
    </default>

    <asset>
        <mesh name="base_link" file="base_link.STL" />
        <mesh name="leg_convex" file="leg_convex.STL" />

        <texture name="skybox" type="skybox" builtin="gradient" rgb1=".4 .6 .8" rgb2="0 0 0" width="1024" height="1024" mark="random" markrgb="1 1 1"/>
        <texture name="texplane" type="2d" builtin="checker" rgb1="0.5961 0.5647 0.4784" rgb2="0.3843 0.32941 0.19215" width="512" height="512" mark="cross" markrgb=".8 .8 .8"/>
        <material name="matplane" reflectance="0.3" texture="texplane" texrepeat="1 1" texuniform="true"/>
    </asset>

    <worldbody>
        <light directional="true" diffuse=".8 .8 .8" specular="0.1 0.1 0.1" pos="0 0 2.5" dir="0 0 -1" castshadow="false"/>
        <geom name="ground" type="plane" size="6 6 1" pos="0 0 0" quat="1 0 0 0" material="matplane" condim="1"/>

        <body name="base_link" pos="0 0 0.15">
          <joint armature="0" axis="1 0 0" damping="0" limited="false" name="rootx" pos="0 0 0" stiffness="0" type="slide"/>
          <joint armature="0" axis="0 0 1" damping="0" limited="false" name="rootz" pos="0 0 0" stiffness="0" type="slide"/>
          <joint armature="0" axis="0 1 0" damping="0" limited="false" name="rooty" pos="0 0 0" stiffness="0" type="hinge"/>

          <geom type="mesh" rgba="0.5 0.0 0.5 1" mesh="base_link" />
          <inertial pos="0.0 0.0 0" mass="2.0477746" diaginertia="0.5 0.5 0.5" />

          <site name="head" pos="0.15 0 0" rgba="1 0 0 0.5" size="0.01 0.01 0.01" />

          <!-- right side -->

          <body childclass="leg" name="rear_link" pos="-0.11175 0. -0.02995">
            <joint name="rear_joint"/>
            <body name="rear_right_link" pos="0.0 -0.106162 0.0">
                <geom />
                <inertial pos="-0.0146232 -0.0398438 0" mass="0.0477746" diaginertia="0.001 0.001 0.001" />
            </body>
            <body name="rear_left_link" pos="0.0 0.106162 -0.0">
                <geom />
                <inertial pos="-0.0146232 -0.0398438 0" mass="0.0477746" diaginertia="0.001 0.001 0.001" />
            </body>
          </body>

          <body childclass="leg" name="mid_link" pos="0 0. -0.02995">
            <joint name="mid_joint"/>
            <body name="mid_right_link" pos="0 -0.117162 0.0">
                <inertial pos="-0.0146232 -0.0398438 0" mass="0.0477746" diaginertia="0.001 0.001 0.001" />
                <geom />
            </body>
            <body name="mid_left_link" pos="0 0.117162 0.0">
                <inertial pos="-0.0146232 -0.0398438 0" mass="0.0477746" diaginertia="0.001 0.001 0.001" />
                <geom />
            </body>
          </body>

          <body childclass="leg" name="front_link" pos="0.11175 0.0 -0.02995">
            <joint name="front_joint"/>
            <body name="front_right_link" pos="0. -0.106162 0.0">
                <inertial pos="-0.0146232 -0.0398438 0" mass="0.0477746" diaginertia="0.001 0.001 0.001" />
                <geom />
            </body>
            <body name="front_left_link" pos="0.0 0.106162 0.0">
                <inertial pos="-0.0146232 -0.0398438 0" mass="0.0477746" diaginertia="0.001 0.001 0.001" />
                <geom />
            </body>
          </body>
        </body>

    </worldbody>

    <actuator >
        <position joint="rear_joint" class="leg_actuator"/>
        <position joint="mid_joint" class="leg_actuator"/>
        <position joint="front_joint" class="leg_actuator"/>
  </actuator>
</mujoco>
